<?xml version="1.0" ?>
<sdf version="1.6">
    <model name='rover_differential'>

        <!--base_link-->
        <link name='base_link'>
            <pose relative_to='__model__'>0 0 0.1 0 0 0</pose>
            <inertial>
                <mass>1.14395</mass>
                <inertia>
                    <ixx>0.095329</ixx>
                    <ixy>0</ixy>
                    <ixz>0</ixz>
                    <iyy>0.381317</iyy>
                    <iyz>0</iyz>
                    <izz>0.476646</izz>
                </inertia>
            </inertial>
            <visual name='visual'>
                <geometry>
                    <box>
                        <size>0.5 0.25 0.1</size>
                    </box>
                </geometry>
                <material>
                    <ambient>0.0 0.0 1.0 1</ambient>
                    <diffuse>0.0 0.0 1.0 1</diffuse>
                    <specular>0.0 0.0 1.0 1</specular>
                </material>
            </visual>
            <collision name='collision'>
                <geometry>
                    <box>
                        <size>0.5 0.25 0.1</size>
                    </box>
                </geometry>
            </collision>
            <!--Sensors-->
            <sensor name="imu_sensor" type="imu">
				<always_on>1</always_on>
				<update_rate>250</update_rate>
				<imu>
					<angular_velocity>
						<x>
						<noise type="gaussian">
							<mean>0</mean>
							<stddev>0.0003394</stddev>
							<dynamic_bias_stddev>3.8785e-05</dynamic_bias_stddev>
							<dynamic_bias_correlation_time>1000</dynamic_bias_correlation_time>
						</noise>
						</x>
						<y>
						<noise type="gaussian">
							<mean>0</mean>
							<stddev>0.0003394</stddev>
							<dynamic_bias_stddev>3.8785e-05</dynamic_bias_stddev>
							<dynamic_bias_correlation_time>1000</dynamic_bias_correlation_time>
						</noise>
						</y>
						<z>
						<noise type="gaussian">
							<mean>0</mean>
							<stddev>0.0003394</stddev>
							<dynamic_bias_stddev>3.8785e-05</dynamic_bias_stddev>
							<dynamic_bias_correlation_time>1000</dynamic_bias_correlation_time>
						</noise>
						</z>
					</angular_velocity>
					<linear_acceleration>
						<x>
						<noise type="gaussian">
							<mean>0</mean>
							<stddev>0.004</stddev>
							<dynamic_bias_stddev>0.006</dynamic_bias_stddev>
							<dynamic_bias_correlation_time>300</dynamic_bias_correlation_time>
						</noise>
						</x>
						<y>
						<noise type="gaussian">
							<mean>0</mean>
							<stddev>0.004</stddev>
							<dynamic_bias_stddev>0.006</dynamic_bias_stddev>
							<dynamic_bias_correlation_time>300</dynamic_bias_correlation_time>
						</noise>
						</y>
						<z>
						<noise type="gaussian">
							<mean>0</mean>
							<stddev>0.004</stddev>
							<dynamic_bias_stddev>0.006</dynamic_bias_stddev>
							<dynamic_bias_correlation_time>300</dynamic_bias_correlation_time>
						</noise>
						</z>
					</linear_acceleration>
				</imu>
			</sensor>
            <sensor name="magnetometer_sensor" type="magnetometer">
				<always_on>1</always_on>
				<update_rate>100</update_rate>
				<magnetometer>
					<x>
						<noise type="gaussian">
						<stddev>0.0001</stddev>
						</noise>
					</x>
					<y>
						<noise type="gaussian">
						<stddev>0.0001</stddev>
						</noise>
					</y>
					<z>
						<noise type="gaussian">
						<stddev>0.0001</stddev>
						</noise>
					</z>
				</magnetometer>
			</sensor>
			<sensor name="navsat_sensor" type="navsat">
				<always_on>1</always_on>
				<update_rate>30</update_rate>
			</sensor>
            <sensor name="air_pressure_sensor" type="air_pressure">
				<always_on>1</always_on>
				<update_rate>50</update_rate>
				<air_pressure>
					<pressure>
						<noise type="gaussian">
							<mean>0</mean>
							<stddev>0.01</stddev>
						</noise>
					</pressure>
				</air_pressure>
			</sensor>
        </link>

        <!--Rear Wheel Left-->
        <link name='rear_wheel_left'>
            <pose relative_to="base_link">-0.15 0.15 -0.025 -1.5707 0 0</pose>
            <inertial>
                <mass>1</mass>
                <inertia>
                    <ixx>0.043333</ixx>
                    <ixy>0</ixy>
                    <ixz>0</ixz>
                    <iyy>0.043333</iyy>
                    <iyz>0</iyz>
                    <izz>0.08</izz>
                </inertia>
            </inertial>
            <visual name='visual'>
                <geometry>
                    <cylinder>
                        <radius>0.075</radius>
                        <length>0.05</length>
                    </cylinder>
                </geometry>
                <material>
                    <ambient>1.0 0.0 0.0 1</ambient>
                    <diffuse>1.0 0.0 0.0 1</diffuse>
                    <specular>1.0 0.0 0.0 1</specular>
                </material>
            </visual>
            <collision name='collision'>
                <geometry>
                    <cylinder>
                        <radius>0.075</radius>
                        <length>0.05</length>
                    </cylinder>
                </geometry>
            </collision>
        </link>

        <!--Rear Wheel Right-->
        <link name='rear_wheel_right'>
            <pose relative_to="base_link">-0.15 -0.15 -0.025 -1.5707 0 0</pose>
            <inertial>
                <mass>1</mass>
                <inertia>
                    <ixx>0.043333</ixx>
                    <ixy>0</ixy>
                    <ixz>0</ixz>
                    <iyy>0.043333</iyy>
                    <iyz>0</iyz>
                    <izz>0.08</izz>
                </inertia>
            </inertial>
            <visual name='visual'>
                <geometry>
                    <cylinder>
                        <radius>0.075</radius>
                        <length>0.05</length>
                    </cylinder>
                </geometry>
                <material>
                    <ambient>1.0 0.0 0.0 1</ambient>
                    <diffuse>1.0 0.0 0.0 1</diffuse>
                    <specular>1.0 0.0 0.0 1</specular>
                </material>
            </visual>
            <collision name='collision'>
                <geometry>
                    <cylinder>
                        <radius>0.075</radius>
                        <length>0.05</length>
                    </cylinder>
                </geometry>
            </collision>
        </link>

        <!--caster wheel-->
        <link name='caster'>
            <pose relative_to="base_link">0.15 0 -0.025 -1.5707 0 0</pose>
            <inertial>
                <mass>1</mass>
                <inertia>
                    <ixx>0.016</ixx>
                    <ixy>0</ixy>
                    <ixz>0</ixz>
                    <iyy>0.016</iyy>
                    <iyz>0</iyz>
                    <izz>0.016</izz>
                </inertia>
            </inertial>
            <visual name='visual'>
                <geometry>
                    <sphere>
                        <radius>0.075</radius>
                    </sphere>
                </geometry>
                <material>
                    <ambient>0.0 1 0.0 1</ambient>
                    <diffuse>0.0 1 0.0 1</diffuse>
                    <specular>0.0 1 0.0 1</specular>
                </material>
            </visual>
            <collision name='collision'>
                <geometry>
                    <sphere>
                        <radius>0.075</radius>
                    </sphere>
                </geometry>
            </collision>
        </link>

        <!--left wheel joint-->
        <joint name='rear_wheel_left_joint' type='revolute'>
            <pose relative_to='rear_wheel_left'/>
            <parent>base_link</parent>
            <child>rear_wheel_left</child>
            <axis>
                <xyz expressed_in='__model__'>0 1 0</xyz>
                <limit>
                    <lower>-1.79769e+308</lower>
                    <upper>1.79769e+308</upper>
                </limit>
            </axis>
        </joint>

        <!--right wheel joint-->
        <joint name='rear_wheel_right_joint' type='revolute'>
            <pose relative_to='rear_wheel_right'/>
            <parent>base_link</parent>
            <child>rear_wheel_right</child>
            <axis>
                <xyz expressed_in='__model__'>0 1 0</xyz>
                <limit>
                    <lower>-1.79769e+308</lower>
                    <upper>1.79769e+308</upper>
                </limit>
            </axis>
        </joint>

        <!--caster wheel joint-->
        <joint name='caster_wheel' type='ball'>
            <pose relative_to='caster'/>
            <parent>base_link</parent>
            <child>caster</child>
        </joint>

        <!--Plugins-->
        <plugin filename="gz-sim-joint-controller-system" name="gz::sim::systems::JointController">
            <joint_name>rear_wheel_left_joint</joint_name>
            <sub_topic>command/motor_speed</sub_topic>
            <use_actuator_msg>true</use_actuator_msg>
            <actuator_number>1</actuator_number>
            <p_gain>10.0</p_gain>
	    </plugin>
	    <plugin filename="gz-sim-joint-controller-system" name="gz::sim::systems::JointController">
	        <joint_name>rear_wheel_right_joint</joint_name>
	        <sub_topic>command/motor_speed</sub_topic>
		    <use_actuator_msg>true</use_actuator_msg>
	        <actuator_number>0</actuator_number>
	        <p_gain>10.0</p_gain>
	    </plugin>
        <plugin filename="gz-sim-joint-state-publisher-system" name="gz::sim::systems::JointStatePublisher">
			<joint_name>rear_wheel_left_joint</joint_name>
			<joint_name>rear_wheel_right_joint</joint_name>
		</plugin>
    </model>
</sdf>
