<?xml version="1.0" encoding="UTF-8"?>
<sdf version='1.9'>
  <model name='w_beta_motors'>
    <link name="motors_attach_link">
    </link>
    <joint name='motor1_joint' type='revolute'>
      <pose relative_to='motors_attach_link'>0.232905435027709 -0.680975950313778 0.086799987792292504 0 0 0</pose>
      <parent>motors_attach_link</parent>
      <child>motor1_link</child>
      <axis>
        <xyz>0 0 -1</xyz>
        <limit>
          <lower>-inf</lower>
          <upper>inf</upper>
        </limit>
        <dynamics>
          <spring_reference>0</spring_reference>
          <spring_stiffness>0</spring_stiffness>
        </dynamics>
      </axis>
    </joint>
    <link name='motor1_link'>
      <pose relative_to='motor1_joint'>0 0 0 0 0 0</pose>
      <inertial>
        <pose>0.0013718469714564 0.00045606731450897902 0.0073133449794331997 0 0 0</pose>
        <mass>0.091055401402339503</mass>
        <inertia>
          <ixx>0.0017997098022500199</ixx>
          <ixy>0.00059831592731370399</ixy>
          <ixz>-2.9180888247381602e-06</ixz>
          <iyy>0.00020796254990806899</iyy>
          <iyz>-9.7400626864641191e-07</iyz>
          <izz>0.0019993487307220599</izz>
        </inertia>
      </inertial>
      <collision name='motor1_link_collision'>
        <pose>0 0 0 0 0 0</pose>
        <geometry>
          <!-- <mesh>
            <scale>1 1 1</scale>
            <uri>model://w_beta_motors/meshes/motor1_link.STL</uri>
          </mesh> -->
        </geometry>
      </collision>
      <visual name='motor1_link_visual'>
        <pose>0 0 0 0 0 0</pose>
        <geometry>
          <mesh>
            <scale>1 1 1</scale>
            <uri>model://w_beta_motors/meshes/motor1_link.STL</uri>
          </mesh>
        </geometry>
        <material>
          <diffuse>0.990196109 1 1 1</diffuse>
          <ambient>0.990196109 1 1 1</ambient>
        </material>
      </visual>
    </link>
    <joint name='motor2_joint' type='revolute'>
      <pose relative_to='motors_attach_link'>0.23290543502750999 0.68099894846030495 0.086799987792292504 0 0 0</pose>
      <parent>motors_attach_link</parent>
      <child>motor2_link</child>
      <axis>
        <xyz>0 0 -1</xyz>
        <limit>
          <lower>-inf</lower>
          <upper>inf</upper>
        </limit>
        <dynamics>
          <spring_reference>0</spring_reference>
          <spring_stiffness>0</spring_stiffness>
        </dynamics>
      </axis>
    </joint>
    <link name='motor2_link'>
      <pose relative_to='motor2_joint'>0 0 0 0 0 0</pose>
      <inertial>
        <pose>-0.0014305032114755899 -0.00021090659012745801 0.0073135866330750199 0 0 0</pose>
        <mass>0.091056722623615596</mass>
        <inertia>
          <ixx>0.00195635507139776</ixx>
          <ixy>0.00029002882339814102</ixy>
          <ixz>3.0428743722712e-06</ixz>
          <iyy>5.1323748601635897e-05</iyy>
          <iyz>4.5325872488288102e-07</iyz>
          <izz>0.0019993550610476201</izz>
        </inertia>
      </inertial>
      <collision name='motor2_link_collision'>
        <pose>0 0 0 0 0 0</pose>
        <geometry>
          <!-- <mesh>
            <scale>1 1 1</scale>
            <uri>model://w_beta_motors/meshes/motor2_link.STL</uri>
          </mesh> -->
        </geometry>
      </collision>
      <visual name='motor2_link_visual'>
        <pose>0 0 0 0 0 0</pose>
        <geometry>
          <mesh>
            <scale>1 1 1</scale>
            <uri>model://w_beta_motors/meshes/motor2_link.STL</uri>
          </mesh>
        </geometry>
        <material>
          <diffuse>0.990196109 1 1 1</diffuse>
          <ambient>0.990196109 1 1 1</ambient>
        </material>
      </visual>
    </link>
    <joint name='motor3_joint' type='revolute'>
      <pose relative_to='motors_attach_link'>-0.32790634716345701 0.73263569922032301 -0.033550012207737803 0 0 0</pose>
      <parent>motors_attach_link</parent>
      <child>motor3_link</child>
      <axis>
        <xyz>0 0 -1</xyz>
        <limit>
          <lower>-inf</lower>
          <upper>inf</upper>
        </limit>
        <dynamics>
          <spring_reference>0</spring_reference>
          <spring_stiffness>0</spring_stiffness>
        </dynamics>
      </axis>
    </joint>
    <link name='motor3_link'>
      <pose relative_to='motor3_joint'>0 0 0 0 0 0</pose>
      <inertial>
        <pose>-0.0013718027474161601 -0.00045616980930340801 0.0073133274877710099 0 0 0</pose>
        <mass>0.091055296133623898</mass>
        <inertia>
          <ixx>0.0017997089058008301</ixx>
          <ixy>0.000598315540688855</ixy>
          <ixz>2.9180241614739701e-06</ixz>
          <iyy>0.00020796235892841001</iyy>
          <iyz>9.7416410668095493e-07</iyz>
          <izz>0.00199934769343766</izz>
        </inertia>
      </inertial>
      <collision name='motor3_link_collision'>
        <pose>0 0 0 0 0 0</pose>
        <geometry>
          <!-- <mesh>
            <scale>1 1 1</scale>
            <uri>model://w_beta_motors/meshes/motor3_link.STL</uri>
          </mesh> -->
        </geometry>
      </collision>
      <visual name='motor3_link_visual'>
        <pose>0 0 0 0 0 0</pose>
        <geometry>
          <mesh>
            <scale>1 1 1</scale>
            <uri>model://w_beta_motors/meshes/motor3_link.STL</uri>
          </mesh>
        </geometry>
        <material>
          <diffuse>0.990196109 1 1 1</diffuse>
          <ambient>0.990196109 1 1 1</ambient>
        </material>
      </visual>
    </link>
    <joint name='motor4_joint' type='revolute'>
      <pose relative_to='motors_attach_link'>-0.32790634716328698 -0.73263569922915805 -0.033550012207681001 0 0 0</pose>
      <parent>motors_attach_link</parent>
      <child>motor4_link</child>
      <axis>
        <xyz>0 0 -1</xyz>
        <limit>
          <lower>-inf</lower>
          <upper>inf</upper>
        </limit>
        <dynamics>
          <spring_reference>0</spring_reference>
          <spring_stiffness>0</spring_stiffness>
        </dynamics>
      </axis>
    </joint>
    <link name='motor4_link'>
      <pose relative_to='motor4_joint'>0 0 0 0 0 0</pose>
      <inertial>
        <pose>0.0014305394353528701 0.00021075342762255601 0.0073136083419090498 0 0 0</pose>
        <mass>0.091056825312321704</mass>
        <inertia>
          <ixx>0.00195635690033652</ixx>
          <ixy>0.00029002920953167697</ixy>
          <ixz>-3.0429229474669701e-06</ixz>
          <iyy>5.1323862673045503e-05</iyy>
          <iyz>-4.5304453840861302e-07</iyz>
          <izz>0.00199935693898753</izz>
        </inertia>
      </inertial>
      <collision name='motor4_link_collision'>
        <pose>0 0 0 0 0 0</pose>
        <geometry>
          <!-- <mesh>
            <scale>1 1 1</scale>
            <uri>model://w_beta_motors/meshes/motor4_link.STL</uri>
          </mesh> -->
        </geometry>
      </collision>
      <visual name='motor4_link_visual'>
        <pose>0 0 0 0 0 0</pose>
        <geometry>
          <mesh>
            <scale>1 1 1</scale>
            <uri>model://w_beta_motors/meshes/motor4_link.STL</uri>
          </mesh>
        </geometry>
        <material>
          <diffuse>0.990196109 1 1 1</diffuse>
          <ambient>0.990196109 1 1 1</ambient>
        </material>
      </visual>
    </link>
    <joint name='motor5_joint' type='revolute'>
      <pose relative_to='motors_attach_link'>0.23290543502762401 0.68099894846028297 -0.025799987792194799 0 0 0</pose>
      <parent>motors_attach_link</parent>
      <child>motor5_link</child>
      <axis>
        <xyz>0 0 -1</xyz>
        <limit>
          <lower>-inf</lower>
          <upper>inf</upper>
        </limit>
        <dynamics>
          <spring_reference>0</spring_reference>
          <spring_stiffness>0</spring_stiffness>
        </dynamics>
      </axis>
    </joint>
    <link name='motor5_link'>
      <pose relative_to='motor5_joint'>0 0 0 0 0 0</pose>
      <inertial>
        <pose>0.00144206884039741 0.00010457013763298699 -0.00731347329195931 0 0 0</pose>
        <mass>0.091055764859041002</mass>
        <inertia>
          <ixx>0.0019895629809236598</ixx>
          <ixy>0.00014047468210117201</ixy>
          <ixz>3.0686609132952299e-06</ixz>
          <iyy>1.81062769655122e-05</iyy>
          <iyz>2.1778521508269101e-07</iyz>
          <izz>0.0019993456337022001</izz>
        </inertia>
      </inertial>
      <collision name='motor5_link_collision'>
        <pose>0 0 0 0 0 0</pose>
        <geometry>
          <!-- <mesh>
            <scale>1 1 1</scale>
            <uri>model://w_beta_motors/meshes/motor5_link.STL</uri>
          </mesh> -->
        </geometry>
      </collision>
      <visual name='motor5_link_visual'>
        <pose>0 0 0 0 0 0</pose>
        <geometry>
          <mesh>
            <scale>1 1 1</scale>
            <uri>model://w_beta_motors/meshes/motor5_link.STL</uri>
          </mesh>
        </geometry>
        <material>
          <diffuse>0.990196109 1 1 1</diffuse>
          <ambient>0.990196109 1 1 1</ambient>
        </material>
      </visual>
    </link>
    <joint name='motor6_joint' type='revolute'>
      <pose relative_to='motors_attach_link'>0.23290543502750999 -0.68097595031382396 -0.0257999877923085 0 0 0</pose>
      <parent>motors_attach_link</parent>
      <child>motor6_link</child>
      <axis>
        <xyz>0 0 -1</xyz>
        <limit>
          <lower>-inf</lower>
          <upper>inf</upper>
        </limit>
        <dynamics>
          <spring_reference>0</spring_reference>
          <spring_stiffness>0</spring_stiffness>
        </dynamics>
      </axis>
    </joint>
    <link name='motor6_link'>
      <pose relative_to='motor6_joint'>0 0 0 0 0 0</pose>
      <inertial>
        <pose>-0.0014019666907453001 -0.00035278058782373101 -0.00731336261518518 0 0 0</pose>
        <mass>0.091055458263771205</mass>
        <inertia>
          <ixx>0.0018820721822407</ixx>
          <ixy>0.00046914297123356702</ixy>
          <ixz>-2.9843838418467101e-06</ixz>
          <iyy>0.00012559846268942699</iyy>
          <iyz>-7.4656086728988697e-07</iyz>
          <izz>0.0019993470429182599</izz>
        </inertia>
      </inertial>
      <collision name='motor6_link_collision'>
        <pose>0 0 0 0 0 0</pose>
        <geometry>
          <!-- <mesh>
            <scale>1 1 1</scale>
            <uri>model://w_beta_motors/meshes/motor6_link.STL</uri>
          </mesh> -->
        </geometry>
      </collision>
      <visual name='motor6_link_visual'>
        <pose>0 0 0 0 0 0</pose>
        <geometry>
          <mesh>
            <scale>1 1 1</scale>
            <uri>model://w_beta_motors/meshes/motor6_link.STL</uri>
          </mesh>
        </geometry>
        <material>
          <diffuse>0.990196109 1 1 1</diffuse>
          <ambient>0.990196109 1 1 1</ambient>
        </material>
      </visual>
    </link>
    <joint name='motor7_joint' type='revolute'>
      <pose relative_to='motors_attach_link'>-0.32790634716331502 -0.73263569922916505 -0.146149987792282 0 0 0</pose>
      <parent>motors_attach_link</parent>
      <child>motor7_link</child>
      <axis>
        <xyz>0 0 -1</xyz>
        <limit>
          <lower>-inf</lower>
          <upper>inf</upper>
        </limit>
        <dynamics>
          <spring_reference>0</spring_reference>
          <spring_stiffness>0</spring_stiffness>
        </dynamics>
      </axis>
    </joint>
    <link name='motor7_link'>
      <pose relative_to='motor7_joint'>0 0 0 0 0 0</pose>
      <inertial>
        <pose>-0.00166101285024139 -0.000120465167883221 -0.0072548228527559598 0 0 0</pose>
        <mass>0.079054414580314397</mass>
        <inertia>
          <ixx>0.0019887982013668199</ixx>
          <ixy>0.000140474760503411</ixy>
          <ixz>-3.0686766060765701e-06</ixz>
          <iyy>1.7340530468496e-05</iyy>
          <iyz>-2.17810643749924e-07</iyz>
          <izz>0.00199783301883896</izz>
        </inertia>
      </inertial>
      <collision name='motor7_link_collision'>
        <pose>0 0 0 0 0 0</pose>
        <geometry>
          <!-- <mesh>
            <scale>1 1 1</scale>
            <uri>model://w_beta_motors/meshes/motor7_link.STL</uri>
          </mesh> -->
        </geometry>
      </collision>
      <visual name='motor7_link_visual'>
        <pose>0 0 0 0 0 0</pose>
        <geometry>
          <mesh>
            <scale>1 1 1</scale>
            <uri>model://w_beta_motors/meshes/motor7_link.STL</uri>
          </mesh>
        </geometry>
        <material>
          <diffuse>0.990196109 1 1 1</diffuse>
          <ambient>0.990196109 1 1 1</ambient>
        </material>
      </visual>
    </link>
    <joint name='motor8_joint' type='revolute'>
      <pose relative_to='motors_attach_link'>-0.32790634716323003 0.73263569922035099 -0.14614998779233901 0 0 0</pose>
      <parent>motors_attach_link</parent>
      <child>motor8_link</child>
      <axis>
        <xyz>0 0 -1</xyz>
        <limit>
          <lower>-inf</lower>
          <upper>inf</upper>
        </limit>
        <dynamics>
          <spring_reference>0</spring_reference>
          <spring_stiffness>0</spring_stiffness>
        </dynamics>
      </axis>
    </joint>
    <link name='motor8_link'>
      <pose relative_to='motor8_joint'>0 0 0 0 0 0</pose>
      <inertial>
        <pose>0.00140196642899793 0.00035278039145292299 -0.0073133608665574799 0 0 0</pose>
        <mass>0.091055432799156497</mass>
        <inertia>
          <ixx>0.0018820720184547399</ixx>
          <ixy>0.00046914295333832698</ixy>
          <ixz>2.9843818041830602e-06</ixz>
          <iyy>0.000125598459607257</iyy>
          <iyz>7.4656547086783298e-07</iyz>
          <izz>0.0019993468762170802</izz>
        </inertia>
      </inertial>
      <collision name='motor8_link_collision'>
        <pose>0 0 0 0 0 0</pose>
        <geometry>
          <!-- <mesh>
            <scale>1 1 1</scale>
            <uri>model://w_beta_motors/meshes/motor8_link.STL</uri>
          </mesh> -->
        </geometry>
      </collision>
      <visual name='motor8_link_visual'>
        <pose>0 0 0 0 0 0</pose>
        <geometry>
          <mesh>
            <scale>1 1 1</scale>
            <uri>model://w_beta_motors/meshes/motor8_link.STL</uri>
          </mesh>
        </geometry>
        <material>
          <diffuse>0.990196109 1 1 1</diffuse>
          <ambient>0.990196109 1 1 1</ambient>
        </material>
      </visual>
    </link>
    <plugin filename="gz-sim-multicopter-motor-model-system" name="gz::sim::systems::MulticopterMotorModel">
      <jointName>motor1_joint</jointName>
      <linkName>motor1_link</linkName>
      <turningDirection>ccw</turningDirection>
      <timeConstantUp>0.0125</timeConstantUp>
      <timeConstantDown>0.025</timeConstantDown>
      <maxRotVelocity>521</maxRotVelocity>
      <motorConstant>0.0002888</motorConstant>
      <momentConstant>0.07077</momentConstant>
      <commandSubTopic>command/motor_speed</commandSubTopic>
      <motorNumber>0</motorNumber>
      <rotorDragCoefficient>0.000919012</rotorDragCoefficient>
      <rollingMomentCoefficient>1e-06</rollingMomentCoefficient>
      <rotorVelocitySlowdownSim>10</rotorVelocitySlowdownSim>
      <motorType>velocity</motorType>
    </plugin>
    <plugin filename="gz-sim-multicopter-motor-model-system" name="gz::sim::systems::MulticopterMotorModel">
      <jointName>motor2_joint</jointName>
      <linkName>motor2_link</linkName>
      <turningDirection>cw</turningDirection>
      <timeConstantUp>0.0125</timeConstantUp>
      <timeConstantDown>0.025</timeConstantDown>
      <maxRotVelocity>521</maxRotVelocity>
      <motorConstant>0.0002888</motorConstant>
      <momentConstant>0.07077</momentConstant>
      <commandSubTopic>command/motor_speed</commandSubTopic>
      <motorNumber>1</motorNumber>
      <rotorDragCoefficient>0.000919012</rotorDragCoefficient>
      <rollingMomentCoefficient>1e-06</rollingMomentCoefficient>
      <rotorVelocitySlowdownSim>10</rotorVelocitySlowdownSim>
      <motorType>velocity</motorType>
    </plugin>
    <plugin filename="gz-sim-multicopter-motor-model-system" name="gz::sim::systems::MulticopterMotorModel">
      <jointName>motor3_joint</jointName>
      <linkName>motor3_link</linkName>
      <turningDirection>ccw</turningDirection>
      <timeConstantUp>0.0125</timeConstantUp>
      <timeConstantDown>0.025</timeConstantDown>
      <maxRotVelocity>521</maxRotVelocity>
      <motorConstant>0.0002888</motorConstant>
      <momentConstant>0.07077</momentConstant>
      <commandSubTopic>command/motor_speed</commandSubTopic>
      <motorNumber>2</motorNumber>
      <rotorDragCoefficient>0.000919012</rotorDragCoefficient>
      <rollingMomentCoefficient>1e-06</rollingMomentCoefficient>
      <rotorVelocitySlowdownSim>10</rotorVelocitySlowdownSim>
      <motorType>velocity</motorType>
    </plugin>
    <plugin filename="gz-sim-multicopter-motor-model-system" name="gz::sim::systems::MulticopterMotorModel">
      <jointName>motor4_joint</jointName>
      <linkName>motor4_link</linkName>
      <turningDirection>cw</turningDirection>
      <timeConstantUp>0.0125</timeConstantUp>
      <timeConstantDown>0.025</timeConstantDown>
      <maxRotVelocity>521</maxRotVelocity>
      <motorConstant>0.0002888</motorConstant>
      <momentConstant>0.07077</momentConstant>
      <commandSubTopic>command/motor_speed</commandSubTopic>
      <motorNumber>3</motorNumber>
      <rotorDragCoefficient>0.000919012</rotorDragCoefficient>
      <rollingMomentCoefficient>1e-06</rollingMomentCoefficient>
      <rotorVelocitySlowdownSim>10</rotorVelocitySlowdownSim>
      <motorType>velocity</motorType>
    </plugin>
    <plugin filename="gz-sim-multicopter-motor-model-system" name="gz::sim::systems::MulticopterMotorModel">
      <jointName>motor5_joint</jointName>
      <linkName>motor5_link</linkName>
      <turningDirection>ccw</turningDirection>
      <timeConstantUp>0.0125</timeConstantUp>
      <timeConstantDown>0.025</timeConstantDown>
      <maxRotVelocity>521</maxRotVelocity>
      <motorConstant>0.0002888</motorConstant>
      <momentConstant>0.07077</momentConstant>
      <commandSubTopic>command/motor_speed</commandSubTopic>
      <motorNumber>4</motorNumber>
      <rotorDragCoefficient>0.000919012</rotorDragCoefficient>
      <rollingMomentCoefficient>1e-06</rollingMomentCoefficient>
      <rotorVelocitySlowdownSim>10</rotorVelocitySlowdownSim>
      <motorType>velocity</motorType>
    </plugin>
    <plugin filename="gz-sim-multicopter-motor-model-system" name="gz::sim::systems::MulticopterMotorModel">
      <jointName>motor6_joint</jointName>
      <linkName>motor6_link</linkName>
      <turningDirection>cw</turningDirection>
      <timeConstantUp>0.0125</timeConstantUp>
      <timeConstantDown>0.025</timeConstantDown>
      <maxRotVelocity>521</maxRotVelocity>
      <motorConstant>0.0002888</motorConstant>
      <momentConstant>0.07077</momentConstant>
      <commandSubTopic>command/motor_speed</commandSubTopic>
      <motorNumber>5</motorNumber>
      <rotorDragCoefficient>0.000919012</rotorDragCoefficient>
      <rollingMomentCoefficient>1e-06</rollingMomentCoefficient>
      <rotorVelocitySlowdownSim>10</rotorVelocitySlowdownSim>
      <motorType>velocity</motorType>
    </plugin>
    <plugin filename="gz-sim-multicopter-motor-model-system" name="gz::sim::systems::MulticopterMotorModel">
      <jointName>motor7_joint</jointName>
      <linkName>motor7_link</linkName>
      <turningDirection>ccw</turningDirection>
      <timeConstantUp>0.0125</timeConstantUp>
      <timeConstantDown>0.025</timeConstantDown>
      <maxRotVelocity>521</maxRotVelocity>
      <motorConstant>0.0002888</motorConstant>
      <momentConstant>0.07077</momentConstant>
      <commandSubTopic>command/motor_speed</commandSubTopic>
      <motorNumber>6</motorNumber>
      <rotorDragCoefficient>0.000919012</rotorDragCoefficient>
      <rollingMomentCoefficient>1e-06</rollingMomentCoefficient>
      <rotorVelocitySlowdownSim>10</rotorVelocitySlowdownSim>
      <motorType>velocity</motorType>
    </plugin>
    <plugin filename="gz-sim-multicopter-motor-model-system" name="gz::sim::systems::MulticopterMotorModel">
      <jointName>motor8_joint</jointName>
      <linkName>motor8_link</linkName>
      <turningDirection>cw</turningDirection>
      <timeConstantUp>0.0125</timeConstantUp>
      <timeConstantDown>0.025</timeConstantDown>
      <maxRotVelocity>521</maxRotVelocity>
      <motorConstant>0.0002888</motorConstant>
      <momentConstant>0.07077</momentConstant>
      <commandSubTopic>command/motor_speed</commandSubTopic>
      <motorNumber>7</motorNumber>
      <rotorDragCoefficient>0.000919012</rotorDragCoefficient>
      <rollingMomentCoefficient>1e-06</rollingMomentCoefficient>
      <rotorVelocitySlowdownSim>10</rotorVelocitySlowdownSim>
      <motorType>velocity</motorType>
    </plugin>
  </model>
</sdf>